<?xml version="1.0"?>

<robot name="mybot">
    <!-- color -->
    <material name="black">
        <color rgba="0.0 0.0 0.0 1.0"/>
    </material>
    <material name="orange">
        <color rgba="1.0 0.4 0.0 1.0"/>
    </material>

    <!-- fixed frame, joint -->
    <link name="base"/>
    <joint name="fixed" type="fixed">
        <parent link="base"/>
        <child link="link1"/>
    </joint>

    <!-- link1 colision part set -->
    <link name="link1">
        <collision>
            <origin xyz="0 0 0.25" rpy="0 0 0"/>
            <geometry>
                <box size="0.1 0.1 0.5"/>
            </geometry>
        </collision>
    <!-- link1 visual part set -->
        <visual>
            <origin xyz="0 0 0.25" rpy="0 0 0"/>
            <geometry>
                <box size="0.1 0.1 0.5"/>
            </geometry>
            <material name="black"/>
        </visual>
    <!-- 원점, 질량, 관성 -->
        <inertial>
            <origin xyz="0 0 0.25" rpy="0 0 0"/>
            <mass value="1"/>
            <inertia ixx="1.0" ixy="0.0" ixz="0.0" iyy="1.0" iyz="0.0" izz="1.0"/>
        </inertial>
    </link>

    <!-- link set -->
    <joint name="joint1" type="revolute">
        <parent link="link1"/>
        <child link="link2"/>
        <origin xyz="0 0 0.5" rpy="0 0 0"/>
        <axis xyz="0 0 1"/>
        <limit effort="30" lower="-2.617" upper="2.617" velocity="1.571"/>
    </joint>

    <link name="link2">
        <collision>
            <origin xyz="0 0 0.25" rpy="0 0 0"/>
            <geometry>
                <box size="0.1 0.1 0.5"/>
            </geometry>
        </collision>
        <visual>
            <origin xyz="0 0 0.25" rpy="0 0 0"/>
            <geometry>
                <box size="0.1 0.1 0.5"/>
            </geometry>
            <material name="orange"/>
        </visual>
        <inertial>
            <origin xyz="0 0 0.25" rpy="0 0 0"/>
            <mass value="1"/>
            <inertia ixx="1.0" ixy="0.0" ixz="0.0" iyy="1.0" iyz="0.0" izz="1.0"/>
        </inertial>
    </link>
    
    <joint name="joint2" type="revolute">
        <parent link="link2"/>
        <child link="link3"/>
        <origin xyz="0 0 0.5" rpy="0 0 0"/>
        <axis xyz="0 01 1"/>
        <limit effort="30" lower="-2.617" upper="2.617" velocity="1.571"/>
    </joint>

    <link name="link3">
        <collision>
            <origin xyz="0 0 0.25" rpy="0 0 0"/>
            <geometry>
                <box size="0.1 0.1 1.0"/>
            </geometry>
        </collision>
        <visual>
            <origin xyz="0 0 0.5" rpy="0 0 0"/>
            <geometry>
                <box size="0.1 0.1 1.1"/>
            </geometry>
            <material name="black"/>
        </visual>
        <inertial>
            <origin xyz="0 0 0.5" rpy="0 0 0"/>
            <mass value="1"/>
            <inertia ixx="1.0" ixy="0.0" ixz="0.0" iyy="1.0" iyz="0.0" izz="1.0"/>
        </inertial>
    </link>
    
    <joint name="joint3" type="revolute">
        <parent link="link3"/>
        <child link="link4"/>
        <origin xyz="0 0 1.0" rpy="0 0 0"/>
        <axis xyz="0 1 0"/>
        <limit effort="30" lower="-2.617" upper="2.617" velocity="1.571"/>
    </joint>

    <link name="link4">
        <collision>
            <origin xyz="0 0 0.25" rpy="0 0 0"/>
            <geometry>
                <box size="0.1 0.1 0.5"/>
            </geometry>
        </collision>
        <visual>
            <origin xyz="0 0 0.25" rpy="0 0 0"/>
            <geometry>
                <box size="0.1 0.1 0.5"/>
            </geometry>
            <material name="orange"/>
        </visual>
        <inertial>
            <origin xyz="0 0 0.25" rpy="0 0 0"/>
            <mass value="1"/>
            <inertia ixx="1.0" ixy="0.0" ixz="0.0" iyy="1.0" iyz="0.0" izz="1.0"/>
        </inertial>
    </link>
</robot>
